Workbook

Sheet Recovered_Sheet1

Sheet 000000

Sheet ปร.4 
A4: t
J5: หน้าที่ 1/1
A6: ส่วนงาน วิศวกรรมท่อร้อยสาย (วทฐ.) | J6: แบบ ปร.4 (ก)
A7: แบบก่อสร้างท่อร้อยสายสื่อสารใต้ดิน
A8: บัญชีราคา งานจ้างเหมาก่อสร้างท่อร้อยสายสื่อสารใต้ดินและ/หรือบ่อพัก | C8: โครงการ ปรับปรุงระบบจำหน่ายไฟฟ้าเป็นเคเบิลใต้ดิน
A9: เส้นทาง | B9: ถนนแสงชูโต (ทางเข้าบ้านเหนือ - โรงเรียนเทศบาล 3) | C9: พื้นที่ก่อสร้าง | D9: ชส.กาญจนบุรี จ.กาญจนบุรี | I9: หน่วย - บาท
A10: ลำดับที่ | B10: รายการ | C10: ปริมาณงาน | D10: หน่วย | E10: ค่าวัสดุ ไม่รวมภาษีมูลค่าเพิ่ม (1) | G10: ค่าแรง ไม่รวมภาษีมูลค่าเพิ่ม (2) | I10: ค่างานต้นทุน | J10: หมายเหตุ | K10: ค่าวัสดุ (1) | L10: ค่าแรง (2) | M10: ค่าวัสดุ (1) | N10: ใหม่ 61 | O10: ค่าแรง (2) | P10: ใหม่ 61 | Q10: ราคาต่อหน่วย | R10: ที่มา | S10: ราคาทุน | T10: Factor F | U10: ราคาต่อหน่วย * FF | V10: ราคากลาง
E11: ราคา/หน่วย | F11: จำนวนเงิน | G11: ราคา/หน่วย | H11: จำนวนเงิน | I11: (3)=(1)+(2)
A12: 1 | B12: งานวางท่อ 1-𝜙1.5" PVC. กลบทราย | C12: 229 | D12: ม. | E12: 401 | F12: =ROUND((C12*E12),0) -> 91829 | G12: 113 | H12: =ROUND((C12*G12),0) -> 25877 | I12: =ROUND((F12+H12),0) -> 117706
A13: 2 | B13: งานวางท่อ 1-𝜙3" PVC. กลบทราย | C13: 3720 | D13: ม. | E13: 450 | F13: =ROUND((C13*E13),0) -> 1674000 | G13: 127 | H13: =ROUND((C13*G13),0) -> 472440 | I13: =ROUND((F13+H13),0) -> 2146440
A14: 3 | B14: งานวางท่อ 2-𝜙3" PVC. กลบทราย (MAIN DUCT) | C14: 4997 | D14: ม. | E14: 569 | F14: =ROUND((C14*E14),0) -> 2843293 | G14: 161 | H14: =ROUND((C14*G14),0) -> 804517 | I14: =ROUND((F14+H14),0) -> 3647810 | K14: =N14*C14 -> 0 | L14: =P14*C14 -> 0 | Q14: =N14+P14 -> 0 | S14: =ROUND((C14*Q14),2) -> 0 | T14: =#REF! -> #REF! | U14: =ROUND((Q14*T14),0) -> #REF! | V14: =ROUND((S14*T14),0) -> #REF!
A15: 4 | B15: งานวางท่อ 2-𝜙3" PVC. กลบทราย (RISER) | C15: 2429 | D15: ม. | E15: 569 | F15: =ROUND((C15*E15),0) -> 1382101 | G15: 161 | H15: =ROUND((C15*G15),0) -> 391069 | I15: =ROUND((F15+H15),0) -> 1773170
A16: 5 | B16: งานดันท่อลอด 2-Ø110 มม. HDPE PN10 (HDD) (MAIN DUCT) | C16: 251 | D16: ม. | E16: 2596 | F16: =ROUND((C16*E16),0) -> 651596 | G16: 732 | H16: =ROUND((C16*G16),0) -> 183732 | I16: =ROUND((F16+H16),0) -> 835328
A17: 6 | B17: งานสร้างบ่อพักย่อย (PB) JUF-6 ฝา ค.ส.ล. ตามแบบมาตรฐานเลขที่ 101 | C17: 4 | D17: บ่อ | E17: 12273 | F17: =ROUND((C17*E17),0) -> 49092 | G17: 3462 | H17: =ROUND((C17*G17),0) -> 13848 | I17: =ROUND((F17+H17),0) -> 62940
A18: 7 | B18: งานสร้างบ่อพัก (PB) JUF-11 ฝาค.ส.ล ตามแบบมาตรฐานเลขที่ 101 | C18: 40 | D18: บ่อ | E18: 18420 | F18: =ROUND((C18*E18),0) -> 736800 | G18: 5196 | H18: =ROUND((C18*G18),0) -> 207840 | I18: =ROUND((F18+H18),0) -> 944640
A19: 8 | B19: งานสร้างบ่อพัก (PB) JUF-11 ฝาเหล็ก ตามแบบมาตรฐานเลขที่ 101 | C19: 3 | D19: บ่อ | E19: 25289 | F19: =ROUND((C19*E19),0) -> 75867 | G19: 7133 | H19: =ROUND((C19*G19),0) -> 21399 | I19: =ROUND((F19+H19),0) -> 97266
A20: 9 | B20: งานสร้างท่อโค้ง 2-𝜙3" ขึ้นเสา ตามแบบมาตรฐานเลขที่ 152 | C20: 50 | D20: จุด | E20: 5067 | F20: =ROUND((C20*E20),0) -> 253350 | G20: 1429 | H20: =ROUND((C20*G20),0) -> 71450 | I20: =ROUND((F20+H20),0) -> 324800 | K20: =N20*C20 -> 0 | L20: =P20*C20 -> 0 | Q20: =N20+P20 -> 0 | S20: =ROUND((C20*Q20),2) -> 0 | T20: =T14 -> #REF! | U20: =ROUND((Q20*T20),0) -> #REF! | V20: =ROUND((S20*T20),0) -> #REF!
A21: 10 | B21: งานปักเสาโทรศัพท์คอนกรีตเสริมเหล็กขนาด 8.00 ม. | C21: 50 | D21: ต้น | E21: 2755 | F21: =ROUND((C21*E21),0) -> 137750 | G21: 777 | H21: =ROUND((C21*G21),0) -> 38850 | I21: =ROUND((F21+H21),0) -> 176600
A22: 11 | B22: เสา STEEL POLE กัลวาไนซ์ หน้ากว้าง3"x3" ยาว 2.20 เมตร. | C22: 101 | D22: ต้น | E22: 3832 | F22: =ROUND((C22*E22),0) -> 387032 | G22: 827 | H22: =ROUND((C22*G22),0) -> 83527 | I22: =ROUND((F22+H22),0) -> 470559 | K22: =N22*C22 -> 0 | L22: =P22*C22 -> 0 | Q22: =N22+P22 -> 0 | S22: =ROUND((C22*Q22),2) -> 0 | T22: =#REF! -> #REF! | U22: =ROUND((Q22*T22),0) -> #REF! | V22: =ROUND((S22*T22),0) -> #REF!
A23: 12 | B23: Riser service | C23: 10 | D23: ชุด | E23: 463 | F23: =ROUND((C23*E23),0) -> 4630 | G23: 130 | H23: =ROUND((C23*G23),0) -> 1300 | I23: =ROUND((F23+H23),0) -> 5930 | K23: =N23*C23 -> 0 | L23: =P23*C23 -> 0 | Q23: =N23+P23 -> 0 | S23: =ROUND((C23*Q23),2) -> 0 | T23: =#REF! -> #REF! | U23: =ROUND((Q23*T23),0) -> #REF! | V23: =ROUND((S23*T23),0) -> #REF!
A24: 13 | B24: งานเจาะผนังบ่อพักย่อย ( PB ) | C24: 44 | D24: จุด | E24: 1087 | F24: =ROUND((C24*E24),0) -> 47828 | G24: 306 | H24: =ROUND((C24*G24),0) -> 13464 | I24: =ROUND((F24+H24),0) -> 61292
A25: 14 | B25: งานเจาะผนังบ่อพักย่อย ( MH ) | C25: 31 | D25: จุด | E25: 2173 | F25: =ROUND((C25*E25),0) -> 67363 | G25: 613 | H25: =ROUND((C25*G25),0) -> 19003 | I25: =ROUND((F25+H25),0) -> 86366
A26: 15 | B26: งานซ่อมคันหิน ตามแบบมาตรฐานเลขที่ ถ. 620/29 | C26: 250 | D26: ม. | E26: 179 | F26: =ROUND((C26*E26),0) -> 44750 | G26: 50 | H26: =ROUND((C26*G26),0) -> 12500 | I26: =ROUND((F26+H26),0) -> 57250
A27: 16 | B27: งานซ่อมทางเท้าปูอิฐอินเตอร์ล็อค(แบบมีสี) ตามมาตรฐานเลขที่ ฟ.1305 | C27: 1306 | D27: ตรม. | E27: 288 | F27: =ROUND((C27*E27),0) -> 376128 | G27: 81 | H27: =ROUND((C27*G27),0) -> 105786 | I27: =ROUND((F27+H27),0) -> 481914
A28: 17 | B28: งานซ่อมทางเท้าปูกระเบื้อง CERAMIC ขนาด 0.30x0.30 ม. (แบบมีสีและลวดลาย) | C28: 4185 | D28: ตรม. | E28: 349 | F28: =ROUND((C28*E28),0) -> 1460565 | G28: 98 | H28: =ROUND((C28*G28),0) -> 410130 | I28: =ROUND((F28+H28),0) -> 1870695
A29: 18 | B29: งานซ่อมถนนแอสฟัลต์ชั่วคราว | C29: 2284 | D29: ตรม. | E29: 214 | F29: =ROUND((C29*E29),0) -> 488776 | G29: 60 | H29: =ROUND((C29*G29),0) -> 137040 | I29: =ROUND((F29+H29),0) -> 625816
A30: 19 | B30: งานซ่อมถนนแอสฟัลต์หนา 0.10 ม.ตามแบบมาตรฐานเลขที่ ถอ.60/29 | C30: 2284 | D30: ตรม. | E30: 481 | F30: =ROUND((C30*E30),0) -> 1098604 | G30: 136 | H30: =ROUND((C30*G30),0) -> 310624 | I30: =ROUND((F30+H30),0) -> 1409228
A31: 20 | B31: งานซ่อมถนนคอนกรีตเสริมเหล็กหนา 0.20 ม. ตามแบบมาตรฐานเลขที่ 20/29 | C31: 2284 | D31: ตรม. | E31: 621 | F31: =ROUND((C31*E31),0) -> 1418364 | G31: 175 | H31: =ROUND((C31*G31),0) -> 399700 | I31: =ROUND((F31+H31),0) -> 1818064 | K31: =N31*C31 -> 0 | L31: =P31*C31 -> 0 | Q31: =N31+P31 -> 0 | S31: =ROUND((C31*Q31),2) -> 0 | T31: =T23 -> #REF! | U31: =ROUND((Q31*T31),0) -> #REF! | V31: =ROUND((S31*T31),0) -> #REF!
A32: 21 | B32: งานทุบถนนคอนกรีตเสริมเหล็ก | C32: 2284 | D32: ตรม. | E32: 0 | F32: =ROUND((C32*E32),0) -> 0 | G32: 279 | H32: =ROUND((C32*G32),0) -> 637236 | I32: =ROUND((F32+H32),0) -> 637236
A33: 22 | B33: งานซ่อมทางเท้าปูแผ่นคอนกรีต ขนาด 0.40 x 0.40 x 0.05 ม. | C33: 347 | D33: ตรม. | E33: 268 | F33: =ROUND((C33*E33),0) -> 92996 | G33: 76 | H33: =ROUND((C33*G33),0) -> 26372 | I33: =ROUND((F33+H33),0) -> 119368
B35: ผลรวมค่างานต้นทุนงานก่อสร้างท่อร้อยสายสื่อสารใต้ดิน | F35: =SUM(F12:F31) -> 13289718 | H35: =SUM(H12:H31) -> 3724096 | I35: =SUM(I12:I34) -> 17770418 | K35: =SUM(K12:K31) -> 0 | L35: =SUM(L12:L31) -> 0 | S35: =SUM(S12:S31) -> 0 | V35: =SUM(V12:V31) -> #REF!
A37: เงื่อนไข Factor F งานก่อสร้างทาง เงินล่วงหน้าจ่าย 0.00 %, เงินประกันผลงานหัก 0.00 %, ดอกเบี้ยเงินกู้ 7.00 % ต่อปี, ค่าภาษีมูลค่าเพิ่ม 7.00 %
A38: หมายเหตุ ทั้งนี้ ราคางานโครงการ/งานก่อสร้าง ไม่ใช่ราคาค่าก่อสร้างที่แท้จริง แต่เป็นเพียงราคาโดยประมาณเท่านั้น
I41: ผู้ประมาณราคา | J41: นาย ชายชาญ ชื่นมีศรี
J42: สิงหาคม 2567
K43: XXX < 5 ลบ. | L43: XXX > 5 ลบ.
K44: =IF(I35<5000000,1.275,) -> 0 | L44: 1.218
I49: งานซ่อมทางเท้าคอนกรีตหน้าทรายขัด
J54: งานซ่อมทางเท้าคอนกรีตหน้าทรายขัด
J55: รวมราคากับคันหิน
...

Sheet สรุป
M2: หน้าที่ 1/1
A4: ส่วนงาน วิศวกรรมท่อร้อยสาย (วทฐ.) | H4: หน้าที่ 1/1
A5: สรุปรวม | B5: ='ปร.4 '!A8 -> บัญชีราคา งานจ้างเหมาก่อสร้างท่อร้อยสายสื่อสารใต้ดินและ/หรือบ่อพัก | C5: ='ปร.4 '!C8 -> โครงการ ปรับปรุงระบบจำหน่ายไฟฟ้าเป็นเคเบิลใต้ดิน
A6: เส้นทาง | B6: ถนนแสงชูโต (ทางเข้าบ้านเหนือ - โรงเรียนเทศบาล 3) | C6: พื้นที่ก่อสร้าง | D6: ='ปร.4 '!D9 -> ชส.กาญจนบุรี จ.กาญจนบุรี | M6: หน่วย : บาท
A7: ที่ | B7: รายละเอียด | C7: ค่างานต้นทุน | D7: Factor < 5 ลบ. | E7: Factor > 5 ลบ. | F7: ค่าก่อสร้าง (ไม่รวม VAT) | G7: ค่าก่อสร้าง (รวม VAT) | H7: หมายเหตุ
F8: รวม - บาท | G8: รวม - บาท
A9: 1 | B9: ค่าวัสดุและค่าแรงไม่รวมภาษีมูลค่าเพิ่ม | C9: ='ปร.4 '!I35 -> 17770418 | D9: ='ปร.4 '!K44 -> 0 | E9: 1.1842 | F9: =IF(D9=1.2733,C9*D9,IF(E9<1.2733,C9*E9,)) -> 21043729
B19: (1) ประมาณราคาก่อสร้างทั้งโครงการ/งานก่อสร้าง ก่อนภาษี | F19: =F9 -> 21043729
B20: (2) ภาษีมูลค่าเพิ่ม 7.00 % | F20: =ROUND((F19*0.07),2) -> 1473061
B21: (1) + (2) รวมประมาณค่าก่อสร้างทั้งโครงการ/งานก่อสร้าง เป็นเงินทั้งสิ้น | G21: =F19+F20 -> 22516790
B23: ประมาณราคาค่าก่อสร้าง ก่อนภาษี | C23: =BAHTTEXT(F19) -> ยี่สิบเอ็ดล้านสี่หมื่นสามพันเจ็ดร้อยยี่สิบเก้าบาทถ้วน
A25: เงื่อนไข Factor F งานก่อสร้างทาง เงินล่วงหน้าจ่าย 0.00 %, เงินประกันผลงานหัก 0.00 %, ดอกเบี้ยเงินกู้ 7.00 % ต่อปี, ค่าภาษีมูลค่าเพิ่ม 7.00 %
A26: หมายเหตุ ทั้งนี้ ราคางานโครงการ/งานก่อสร้าง ไม่ใช่ราคาค่าก่อสร้างที่แท้จริง แต่เป็นเพียงราคาโดยประมาณเท่านั้น
G29: ผู้ประมาณราคา | H29: ='ปร.4 '!J41 -> นาย ชายชาญ ชื่นมีศรี
H30: ='ปร.4 '!J42 -> สิงหาคม 2567
